Workbook

Sheet Dashboard
A1: PORSCHE | DASHBOARD DE VENDAS
A2: Receita, mix de modelos e concentração geográfica · USD · Base sanitizada
A3: Modelo | B3: Todos | D3: Cidade | E3: Todos | G3: Ano da venda | H3: Todos | J3: Pagamento | K3: Todos
A6: VENDAS ANALISADAS | D6: RECEITA TOTAL | G6: TICKET MÉDIO | J6: KM MÉDIA
A7: =SUM(Dados!$I$2:$I$77) -> 76 | D7: =SUMPRODUCT(Dados!$I$2:$I$77,Dados!$E$2:$E$77) -> 9486700.5 | G7: =IFERROR(D7/A7,0) -> 124825.01 | J7: =IFERROR(SUMPRODUCT(Dados!$I$2:$I$77,Dados!$F$2:$F$77)/A7,0) -> 13378.75
A9: 100 linhas na base original; 24 com data inválida foram excluídas de todas as métricas.
A11: Perguntas de negócio
A47: Modelos e cidades: gráficos mostram os 6 maiores na base limpa completa; valores se recalculam com os filtros. Ao selecionar uma cidade ou modelo, o respectivo gráfico destaca essa seleção.
A50: Dados de apoio dos gráficos
A51: Ano da venda | B51: Receita (USD) | D51: Modelo | E51: Receita (USD) | G51: Cidade | H51: Receita (USD) | J51: Forma de pagamento | K51: Vendas
A52: 2024 | B52: =SUMIFS(Dados!$E$2:$E$77,Dados!$C$2:$C$77,A52,Dados!$I$2:$I$77,1) -> 1439050.5 | D52: =IF(Dashboard!$B$3="Todos","911 Turbo S",IF(0=0,Dashboard!$B$3,"")) -> 911 Turbo S | E52: =IF(D52="","",SUMIFS(Dados!$E$2:$E$77,Dados!$B$2:$B$77,D52,Dados!$I$2:$I$77,1)) -> 726300 | G52: =IF(Dashboard!$E$3="Todos","Atlanta",IF(0=0,Dashboard!$E$3,"")) -> Atlanta | H52: =IF(G52="","",SUMIFS(Dados!$E$2:$E$77,Dados!$H$2:$H$77,G52,Dados!$I$2:$I$77,1)) -> 434800 | J52: Wire Transfer | K52: =SUMIFS(Dados!$I$2:$I$77,Dados!$G$2:$G$77,J52,Dados!$I$2:$I$77,1) -> 16
A53: 2025 | B53: =SUMIFS(Dados!$E$2:$E$77,Dados!$C$2:$C$77,A53,Dados!$I$2:$I$77,1) -> 2167500 | D53: =IF(Dashboard!$B$3="Todos","Cayenne Turbo GT",IF(1=0,Dashboard!$B$3,"")) -> Cayenne Turbo GT | E53: =IF(D53="","",SUMIFS(Dados!$E$2:$E$77,Dados!$B$2:$B$77,D53,Dados!$I$2:$I$77,1)) -> 592800 | G53: =IF(Dashboard!$E$3="Todos","New Orleans",IF(1=0,Dashboard!$E$3,"")) -> New Orleans | H53: =IF(G53="","",SUMIFS(Dados!$E$2:$E$77,Dados!$H$2:$H$77,G53,Dados!$I$2:$I$77,1)) -> 361400 | J53: Credit Card | K53: =SUMIFS(Dados!$I$2:$I$77,Dados!$G$2:$G$77,J53,Dados!$I$2:$I$77,1) -> 12
A54: 2026 | B54: =SUMIFS(Dados!$E$2:$E$77,Dados!$C$2:$C$77,A54,Dados!$I$2:$I$77,1) -> 3901150 | D54: =IF(Dashboard!$B$3="Todos","911 Dakar",IF(2=0,Dashboard!$B$3,"")) -> 911 Dakar | E54: =IF(D54="","",SUMIFS(Dados!$E$2:$E$77,Dados!$B$2:$B$77,D54,Dados!$I$2:$I$77,1)) -> 540600 | G54: =IF(Dashboard!$E$3="Todos","Wichita",IF(2=0,Dashboard!$E$3,"")) -> Wichita | H54: =IF(G54="","",SUMIFS(Dados!$E$2:$E$77,Dados!$H$2:$H$77,G54,Dados!$I$2:$I$77,1)) -> 351600 | J54: Cash | K54: =SUMIFS(Dados!$I$2:$I$77,Dados!$G$2:$G$77,J54,Dados!$I$2:$I$77,1) -> 10
A55: 2027 | B55: =SUMIFS(Dados!$E$2:$E$77,Dados!$C$2:$C$77,A55,Dados!$I$2:$I$77,1) -> 1979000 | D55: =IF(Dashboard!$B$3="Todos","Taycan Turbo",IF(3=0,Dashboard!$B$3,"")) -> Taycan Turbo | E55: =IF(D55="","",SUMIFS(Dados!$E$2:$E$77,Dados!$B$2:$B$77,D55,Dados!$I$2:$I$77,1)) -> 475700.5 | G55: =IF(Dashboard!$E$3="Todos","Dallas",IF(3=0,Dashboard!$E$3,"")) -> Dallas | H55: =IF(G55="","",SUMIFS(Dados!$E$2:$E$77,Dados!$H$2:$H$77,G55,Dados!$I$2:$I$77,1)) -> 317200.5 | J55: Lease | K55: =SUMIFS(Dados!$I$2:$I$77,Dados!$G$2:$G$77,J55,Dados!$I$2:$I$77,1) -> 10
D56: =IF(Dashboard!$B$3="Todos","Taycan Turbo S",IF(4=0,Dashboard!$B$3,"")) -> Taycan Turbo S | E56: =IF(D56="","",SUMIFS(Dados!$E$2:$E$77,Dados!$B$2:$B$77,D56,Dados!$I$2:$I$77,1)) -> 432000 | G56: =IF(Dashboard!$E$3="Todos","Seattle",IF(4=0,Dashboard!$E$3,"")) -> Seattle | H56: =IF(G56="","",SUMIFS(Dados!$E$2:$E$77,Dados!$H$2:$H$77,G56,Dados!$I$2:$I$77,1)) -> 313900 | J56: Bank Transfer | K56: =SUMIFS(Dados!$I$2:$I$77,Dados!$G$2:$G$77,J56,Dados!$I$2:$I$77,1) -> 8
D57: =IF(Dashboard!$B$3="Todos","Taycan 4S",IF(5=0,Dashboard!$B$3,"")) -> Taycan 4S | E57: =IF(D57="","",SUMIFS(Dados!$E$2:$E$77,Dados!$B$2:$B$77,D57,Dados!$I$2:$I$77,1)) -> 381600 | G57: =IF(Dashboard!$E$3="Todos","Riverside",IF(5=0,Dashboard!$E$3,"")) -> Riverside | H57: =IF(G57="","",SUMIFS(Dados!$E$2:$E$77,Dados!$H$2:$H$77,G57,Dados!$I$2:$I$77,1)) -> 268900 | J57: Financing | K57: =SUMIFS(Dados!$I$2:$I$77,Dados!$G$2:$G$77,J57,Dados!$I$2:$I$77,1) -> 7
J58: Crypto Payment | K58: =SUMIFS(Dados!$I$2:$I$77,Dados!$G$2:$G$77,J58,Dados!$I$2:$I$77,1) -> 6
J59: ACH Payment | K59: =SUMIFS(Dados!$I$2:$I$77,Dados!$G$2:$G$77,J59,Dados!$I$2:$I$77,1) -> 4
J60: Debit Card | K60: =SUMIFS(Dados!$I$2:$I$77,Dados!$G$2:$G$77,J60,Dados!$I$2:$I$77,1) -> 3

Sheet Dados
A1: Data da venda | B1: Modelo | C1: Ano da venda | D1: Ano-modelo | E1: Preço de venda (USD) | F1: Quilometragem (mi) | G1: Forma de pagamento | H1: Cidade | I1: Incluído nos filtros | K1: Modelos | M1: Cidades | O1: Anos da venda | Q1: Pagamentos
A2: 45365 | B2: 911 Turbo S | C2: 2024 | D2: 2024 | E2: 235000 | F2: 1200 | G2: Wire Transfer | H2: Seattle | I2: =IF(AND(OR(Dashboard!$B$3="Todos",B2=Dashboard!$B$3),OR(Dashboard!$E$3="Todos",H2=Dashboard!$E$3),OR(Dashboard!$H$3="Todos",C2=Dashboard!$H$3),OR(Dashboard!$K$3="Todos",G2=Dashboard!$K$3)),1,0) -> 1 | K2: Todos | M2: Todos | O2: Todos | Q2: Todos
A3: 45400 | B3: Cayenne Coupe | C3: 2024 | D3: 2023 | E3: 112750 | F3: 6400 | G3: Financing | H3: Austin | I3: =IF(AND(OR(Dashboard!$B$3="Todos",B3=Dashboard!$B$3),OR(Dashboard!$E$3="Todos",H3=Dashboard!$E$3),OR(Dashboard!$H$3="Todos",C3=Dashboard!$H$3),OR(Dashboard!$K$3="Todos",G3=Dashboard!$K$3)),1,0) -> 1 | K3: 718 Boxster | M3: Albuquerque | O3: 2024 | Q3: ACH Payment
A4: 45434 | B4: Taycan 4S | C4: 2024 | D4: 2024 | E4: 121000 | F4: 0 | G4: Bank Transfer | H4: Los Angeles | I4: =IF(AND(OR(Dashboard!$B$3="Todos",B4=Dashboard!$B$3),OR(Dashboard!$E$3="Todos",H4=Dashboard!$E$3),OR(Dashboard!$H$3="Todos",C4=Dashboard!$H$3),OR(Dashboard!$K$3="Todos",G4=Dashboard!$K$3)),1,0) -> 1 | K4: 718 Boxster GTS | M4: Anchorage | O4: 2025 | Q4: Bank Transfer
A5: 45510 | B5: Panamera 4 | C5: 2024 | D5: 2023 | E5: 104500 | F5: 14500 | G5: Credit Card | H5: Miami | I5: =IF(AND(OR(Dashboard!$B$3="Todos",B5=Dashboard!$B$3),OR(Dashboard!$E$3="Todos",H5=Dashboard!$E$3),OR(Dashboard!$H$3="Todos",C5=Dashboard!$H$3),OR(Dashboard!$K$3="Todos",G5=Dashboard!$K$3)),1,0) -> 1 | K5: 718 Cayman | M5: Atlanta | O5: 2026 | Q5: Cash
A6: 45484 | B6: 911 Carrera S | C6: 2024 | D6: 2020 | E6: 96300 | F6: 41000 | G6: Lease | H6: New York | I6: =IF(AND(OR(Dashboard!$B$3="Todos",B6=Dashboard!$B$3),OR(Dashboard!$E$3="Todos",H6=Dashboard!$E$3),OR(Dashboard!$H$3="Todos",C6=Dashboard!$H$3),OR(Dashboard!$K$3="Todos",G6=Dashboard!$K$3)),1,0) -> 1 | K6: 718 Cayman GT4 RS | M6: Austin | O6: 2027 | Q6: Credit Card
A7: 45523 | B7: 718 Boxster | C7: 2024 | D7: 2021 | E7: 73500 | F7: 22300 | G7: Debit Card | H7: Chicago | I7: =IF(AND(OR(Dashboard!$B$3="Todos",B7=Dashboard!$B$3),OR(Dashboard!$E$3="Todos",H7=Dashboard!$E$3),OR(Dashboard!$H$3="Todos",C7=Dashboard!$H$3),OR(Dashboard!$K$3="Todos",G7=Dashboard!$K$3)),1,0) -> 1 | K7: 718 Cayman S | M7: Bakersfield | Q7: Crypto Payment
A8: 45537 | B8: Macan GTS | C8: 2024 | D8: 2024 | E8: 95000 | F8: 3500 | G8: Financing | H8: Phoenix | I8: =IF(AND(OR(Dashboard!$B$3="Todos",B8=Dashboard!$B$3),OR(Dashboard!$E$3="Todos",H8=Dashboard!$E$3),OR(Dashboard!$H$3="Todos",C8=Dashboard!$H$3),OR(Dashboard!$K$3="Todos",G8=Dashboard!$K$3)),1,0) -> 1 | K8: 911 Carrera | M8: Boise | Q8: Debit Card
A9: 45552 | B9: Taycan Turbo | C9: 2024 | D9: 2023 | E9: 153200.5 | F9: 11 | G9: ACH Payment | H9: Dallas | I9: =IF(AND(OR(Dashboard!$B$3="Todos",B9=Dashboard!$B$3),OR(Dashboard!$E$3="Todos",H9=Dashboard!$E$3),OR(Dashboard!$H$3="Todos",C9=Dashboard!$H$3),OR(Dashboard!$K$3="Todos",G9=Dashboard!$K$3)),1,0) -> 1 | K9: 911 Carrera Cabriolet | M9: Boston | Q9: Financing
A10: 45423 | B10: Panamera Turbo S | C10: 2024 | D10: 2022 | E10: 132000 | F10: 19250 | G10: Cash | H10: San Jose | I10: =IF(AND(OR(Dashboard!$B$3="Todos",B10=Dashboard!$B$3),OR(Dashboard!$E$3="Todos",H10=Dashboard!$E$3),OR(Dashboard!$H$3="Todos",C10=Dashboard!$H$3),OR(Dashboard!$K$3="Todos",G10=Dashboard!$K$3)),1,0) -> 1 | K10: 911 Carrera GTS | M10: Buffalo | Q10: Lease
A11: 45638 | B11: Cayenne Turbo GT | C11: 2024 | D11: 2024 | E11: 188000 | F11: 2100 | G11: Crypto Payment | H11: Houston | I11: =IF(AND(OR(Dashboard!$B$3="Todos",B11=Dashboard!$B$3),OR(Dashboard!$E$3="Todos",H11=Dashboard!$E$3),OR(Dashboard!$H$3="Todos",C11=Dashboard!$H$3),OR(Dashboard!$K$3="Todos",G11=Dashboard!$K$3)),1,0) -> 1 | K11: 911 Carrera S | M11: Chandler | Q11: Wire Transfer
A12: 45651 | B12: 911 Carrera Cabriolet | C12: 2024 | D12: 2023 | E12: 127800 | F12: 12000 | G12: Credit Card | H12: Atlanta | I12: =IF(AND(OR(Dashboard!$B$3="Todos",B12=Dashboard!$B$3),OR(Dashboard!$E$3="Todos",H12=Dashboard!$E$3),OR(Dashboard!$H$3="Todos",C12=Dashboard!$H$3),OR(Dashboard!$K$3="Todos",G12=Dashboard!$K$3)),1,0) -> 1 | K12: 911 Dakar | M12: Charlotte
A13: 45663 | B13: Macan | C13: 2025 | D13: 2021 | E13: 58900 | F13: 33700 | G13: Bank Transfer | H13: Orlando | I13: =IF(AND(OR(Dashboard!$B$3="Todos",B13=Dashboard!$B$3),OR(Dashboard!$E$3="Todos",H13=Dashboard!$E$3),OR(Dashboard!$H$3="Todos",C13=Dashboard!$H$3),OR(Dashboard!$K$3="Todos",G13=Dashboard!$K$3)),1,0) -> 1 | K13: 911 GT3 | M13: Chesapeake
A14: 45702 | B14: Taycan Cross Turismo | C14: 2025 | D14: 2023 | E14: 118500 | F14: 7800 | G14: Wire Transfer | H14: Charlotte | I14: =IF(AND(OR(Dashboard!$B$3="Todos",B14=Dashboard!$B$3),OR(Dashboard!$E$3="Todos",H14=Dashboard!$E$3),OR(Dashboard!$H$3="Todos",C14=Dashboard!$H$3),OR(Dashboard!$K$3="Todos",G14=Dashboard!$K$3)),1,0) -> 1 | K14: 911 Targa 4S | M14: Chicago
A15: 45737 | B15: 911 Targa 4S | C15: 2025 | D15: 2024 | E15: 158750 | F15: 2500 | G15: Lease | H15: Minneapolis | I15: =IF(AND(OR(Dashboard!$B$3="Todos",B15=Dashboard!$B$3),OR(Dashboard!$E$3="Todos",H15=Dashboard!$E$3),OR(Dashboard!$H$3="Todos",C15=Dashboard!$H$3),OR(Dashboard!$K$3="Todos",G15=Dashboard!$K$3)),1,0) -> 1 | K15: 911 Turbo | M15: Cincinnati
A16: 45744 | B16: Panamera | C16: 2025 | D16: 2020 | E16: 72000 | F16: 49000 | G16: Bank Transfer | H16: Philadelphia | I16: =IF(AND(OR(Dashboard!$B$3="Todos",B16=Dashboard!$B$3),OR(Dashboard!$E$3="Todos",H16=Dashboard!$E$3),OR(Dashboard!$H$3="Todos",C16=Dashboard!$H$3),OR(Dashboard!$K$3="Todos",G16=Dashboard!$K$3)),1,0) -> 1 | K16: 911 Turbo S | M16: Cleveland
A17: 45756 | B17: Macan Electric | C17: 2025 | D17: 2025 | E17: 86500 | F17: 0 | G17: Wire Transfer | H17: San Antonio | I17: =IF(AND(OR(Dashboard!$B$3="Todos",B17=Dashboard!$B$3),OR(Dashboard!$E$3="Todos",H17=Dashboard!$E$3),OR(Dashboard!$H$3="Todos",C17=Dashboard!$H$3),OR(Dashboard!$K$3="Todos",G17=Dashboard!$K$3)),1,0) -> 1 | K17: Cayenne | M17: Colorado Springs
A18: 45789 | B18: Taycan GTS | C18: 2025 | D18: 2023 | E18: 139000 | F18: 6250 | G18: Financing | H18: Raleigh | I18: =IF(AND(OR(Dashboard!$B$3="Todos",B18=Dashboard!$B$3),OR(Dashboard!$E$3="Todos",H18=Dashboard!$E$3),OR(Dashboard!$H$3="Todos",C18=Dashboard!$H$3),OR(Dashboard!$K$3="Todos",G18=Dashboard!$K$3)),1,0) -> 1 | K18: Cayenne Coupe | M18: Corpus Christi
A19: 45826 | B19: Cayenne | C19: 2025 | D19: 2021 | E19: 76800 | F19: 38400 | G19: Credit Card | H19: Detroit | I19: =IF(AND(OR(Dashboard!$B$3="Todos",B19=Dashboard!$B$3),OR(Dashboard!$E$3="Todos",H19=Dashboard!$E$3),OR(Dashboard!$H$3="Todos",C19=Dashboard!$H$3),OR(Dashboard!$K$3="Todos",G19=Dashboard!$K$3)),1,0) -> 1 | K19: Cayenne E-Hybrid | M19: Dallas
A20: 45845 | B20: 911 Carrera GTS | C20: 2025 | D20: 2022 | E20: 119900 | F20: 13600 | G20: Cash | H20: Indianapolis | I20: =IF(AND(OR(Dashboard!$B$3="Todos",B20=Dashboard!$B$3),OR(Dashboard!$E$3="Todos",H20=Dashboard!$E$3),OR(Dashboard!$H$3="Todos",C20=Dashboard!$H$3),OR(Dashboard!$K$3="Todos",G20=Dashboard!$K$3)),1,0) -> 1 | K20: Cayenne S | M20: Detroit
A21: 45860 | B21: Panamera 4 E-Hybrid | C21: 2025 | D21: 2023 | E21: 109250 | F21: 8900 | G21: Lease | H21: Fort Worth | I21: =IF(AND(OR(Dashboard!$B$3="Todos",B21=Dashboard!$B$3),OR(Dashboard!$E$3="Todos",H21=Dashboard!$E$3),OR(Dashboard!$H$3="Todos",C21=Dashboard!$H$3),OR(Dashboard!$K$3="Todos",G21=Dashboard!$K$3)),1,0) -> 1 | K21: Cayenne Turbo | M21: Durham
A22: 45883 | B22: Macan T | C22: 2025 | D22: 2022 | E22: 82000 | F22: 21750 | G22: Wire Transfer | H22: Jacksonville | I22: =IF(AND(OR(Dashboard!$B$3="Todos",B22=Dashboard!$B$3),OR(Dashboard!$E$3="Todos",H22=Dashboard!$E$3),OR(Dashboard!$H$3="Todos",C22=Dashboard!$H$3),OR(Dashboard!$K$3="Todos",G22=Dashboard!$K$3)),1,0) -> 1 | K22: Cayenne Turbo GT | M22: Fort Worth
A23: 45901 | B23: Taycan Turbo S | C23: 2025 | D23: 2025 | E23: 214000 | F23: 0 | G23: Crypto Payment | H23: San Diego | I23: =IF(AND(OR(Dashboard!$B$3="Todos",B23=Dashboard!$B$3),OR(Dashboard!$E$3="Todos",H23=Dashboard!$E$3),OR(Dashboard!$H$3="Todos",C23=Dashboard!$H$3),OR(Dashboard!$K$3="Todos",G23=Dashboard!$K$3)),1,0) -> 1 | K23: Macan | M23: Garland
... A39: 46095 | B39: 911 Carrera S | C39: 2026 | D39: 2022 | E39: 104600 | F39: 15900 | G39: Bank Transfer | H39: Honolulu | I39: =IF(AND(OR(Dashboard!$B$3="Todos",B39=Dashboard!$B$3),OR(Dashboard!$E$3="Todos",H39=Dashboard!$E$3),OR(Dashboard!$H$3="Todos",C39=Dashboard!$H$3),OR(Dashboard!$K$3="Todos",G39=Dashboard!$K$3)),1,0) -> 1 | K39: Taycan Turbo S | M39: Miami
A40: 46120 | B40: Cayenne | C40: 2026 | D40: 2021 | E40: 78400 | F40: 40250 | G40: Cash | H40: Henderson | I40: =IF(AND(OR(Dashboard!$B$3="Todos",B40=Dashboard!$B$3),OR(Dashboard!$E$3="Todos",H40=Dashboard!$E$3),OR(Dashboard!$H$3="Todos",C40=Dashboard!$H$3),OR(Dashboard!$K$3="Todos",G40=Dashboard!$K$3)),1,0) -> 1 | M40: Milwaukee
A41: 46133 | B41: 911 Dakar | C41: 2026 | D41: 2024 | E41: 268900 | F41: 1400 | G41: Credit Card | H41: Riverside | I41: =IF(AND(OR(Dashboard!$B$3="Todos",B41=Dashboard!$B$3),OR(Dashboard!$E$3="Todos",H41=Dashboard!$E$3),OR(Dashboard!$H$3="Todos",C41=Dashboard!$H$3),OR(Dashboard!$K$3="Todos",G41=Dashboard!$K$3)),1,0) -> 1 | M41: Minneapolis
A42: 46141 | B42: Panamera 4 | C42: 2026 | D42: 2023 | E42: 101300 | F42: 12700 | G42: Wire Transfer | H42: Corpus Christi | I42: =IF(AND(OR(Dashboard!$B$3="Todos",B42=Dashboard!$B$3),OR(Dashboard!$E$3="Todos",H42=Dashboard!$E$3),OR(Dashboard!$H$3="Todos",C42=Dashboard!$H$3),OR(Dashboard!$K$3="Todos",G42=Dashboard!$K$3)),1,0) -> 1 | M42: New Orleans
A43: 46147 | B43: Macan S | C43: 2026 | D43: 2021 | E43: 66750 | F43: 29800 | G43: Cash | H43: St. Louis | I43: =IF(AND(OR(Dashboard!$B$3="Todos",B43=Dashboard!$B$3),OR(Dashboard!$E$3="Todos",H43=Dashboard!$E$3),OR(Dashboard!$H$3="Todos",C43=Dashboard!$H$3),OR(Dashboard!$K$3="Todos",G43=Dashboard!$K$3)),1,0) -> 1 | M43: New York
A44: 46156 | B44: Taycan Cross Turismo | C44: 2026 | D44: 2024 | E44: 127900 | F44: 7500 | G44: Lease | H44: Pittsburgh | I44: =IF(AND(OR(Dashboard!$B$3="Todos",B44=Dashboard!$B$3),OR(Dashboard!$E$3="Todos",H44=Dashboard!$E$3),OR(Dashboard!$H$3="Todos",C44=Dashboard!$H$3),OR(Dashboard!$K$3="Todos",G44=Dashboard!$K$3)),1,0) -> 1 | M44: Omaha
A45: 46165 | B45: Cayenne Turbo GT | C45: 2026 | D45: 2025 | E45: 200000 | F45: 1950 | G45: Wire Transfer | H45: Cincinnati | I45: =IF(AND(OR(Dashboard!$B$3="Todos",B45=Dashboard!$B$3),OR(Dashboard!$E$3="Todos",H45=Dashboard!$E$3),OR(Dashboard!$H$3="Todos",C45=Dashboard!$H$3),OR(Dashboard!$K$3="Todos",G45=Dashboard!$K$3)),1,0) -> 1 | M45: Orlando
A46: 46175 | B46: 911 Carrera Cabriolet | C46: 2026 | D46: 2023 | E46: 132000 | F46: 8800 | G46: Crypto Payment | H46: Anchorage | I46: =IF(AND(OR(Dashboard!$B$3="Todos",B46=Dashboard!$B$3),OR(Dashboard!$E$3="Todos",H46=Dashboard!$E$3),OR(Dashboard!$H$3="Todos",C46=Dashboard!$H$3),OR(Dashboard!$K$3="Todos",G46=Dashboard!$K$3)),1,0) -> 1 | M46: Philadelphia
A47: 46188 | B47: 718 Cayman GT4 RS | C47: 2026 | D47: 2024 | E47: 176400 | F47: 600 | G47: Credit Card | H47: Plano | I47: =IF(AND(OR(Dashboard!$B$3="Todos",B47=Dashboard!$B$3),OR(Dashboard!$E$3="Todos",H47=Dashboard!$E$3),OR(Dashboard!$H$3="Todos",C47=Dashboard!$H$3),OR(Dashboard!$K$3="Todos",G47=Dashboard!$K$3)),1,0) -> 1 | M47: Phoenix
A48: 46210 | B48: Macan | C48: 2026 | D48: 2021 | E48: 59000 | F48: 36000 | G48: Financing | H48: Greensboro | I48: =IF(AND(OR(Dashboard!$B$3="Todos",B48=Dashboard!$B$3),OR(Dashboard!$E$3="Todos",H48=Dashboard!$E$3),OR(Dashboard!$H$3="Todos",C48=Dashboard!$H$3),OR(Dashboard!$K$3="Todos",G48=Dashboard!$K$3)),1,0) -> 1 | M48: Pittsburgh
A49: 46223 | B49: Taycan Turbo S | C49: 2026 | D49: 2025 | E49: 218000 | F49: 0 | G49: Wire Transfer | H49: Lincoln | I49: =IF(AND(OR(Dashboard!$B$3="Todos",B49=Dashboard!$B$3),OR(Dashboard!$E$3="Todos",H49=Dashboard!$E$3),OR(Dashboard!$H$3="Todos",C49=Dashboard!$H$3),OR(Dashboard!$K$3="Todos",G49=Dashboard!$K$3)),1,0) -> 1 | M49: Plano
A50: 46120 | B50: 911 Carrera GTS | C50: 2026 | D50: 2024 | E50: 121750 | F50: 5872 | G50: Credit Card | H50: Chandler | I50: =IF(AND(OR(Dashboard!$B$3="Todos",B50=Dashboard!$B$3),OR(Dashboard!$E$3="Todos",H50=Dashboard!$E$3),OR(Dashboard!$H$3="Todos",C50=Dashboard!$H$3),OR(Dashboard!$K$3="Todos",G50=Dashboard!$K$3)),1,0) -> 1 | M50: Raleigh
A51: 46252 | B51: 718 Boxster GTS | C51: 2026 | D51: 2023 | E51: 91500 | F51: 13300 | G51: Lease | H51: Reno | I51: =IF(AND(OR(Dashboard!$B$3="Todos",B51=Dashboard!$B$3),OR(Dashboard!$E$3="Todos",H51=Dashboard!$E$3),OR(Dashboard!$H$3="Todos",C51=Dashboard!$H$3),OR(Dashboard!$K$3="Todos",G51=Dashboard!$K$3)),1,0) -> 1 | M51: Reno
... A65: 46429 | B65: Macan S | C65: 2027 | D65: 2022 | E65: 69800 | F65: 26300 | G65: Financing | H65: Tampa | I65: =IF(AND(OR(Dashboard!$B$3="Todos",B65=Dashboard!$B$3),OR(Dashboard!$E$3="Todos",H65=Dashboard!$E$3),OR(Dashboard!$H$3="Todos",C65=Dashboard!$H$3),OR(Dashboard!$K$3="Todos",G65=Dashboard!$K$3)),1,0) -> 1 | M65: Wichita
A66: 46451 | B66: Panamera | C66: 2027 | D66: 2021 | E66: 81000 | F66: 42 | G66: Cash | H66: Austin | I66: =IF(AND(OR(Dashboard!$B$3="Todos",B66=Dashboard!$B$3),OR(Dashboard!$E$3="Todos",H66=Dashboard!$E$3),OR(Dashboard!$H$3="Todos",C66=Dashboard!$H$3),OR(Dashboard!$K$3="Todos",G66=Dashboard!$K$3)),1,0) -> 1
A67: 46464 | B67: 718 Cayman | C67: 2027 | D67: 2023 | E67: 78900 | F67: 17500 | G67: Debit Card | H67: Seattle | I67: =IF(AND(OR(Dashboard!$B$3="Todos",B67=Dashboard!$B$3),OR(Dashboard!$E$3="Todos",H67=Dashboard!$E$3),OR(Dashboard!$H$3="Todos",C67=Dashboard!$H$3),OR(Dashboard!$K$3="Todos",G67=Dashboard!$K$3)),1,0) -> 1
A68: 46479 | B68: 911 Turbo S | C68: 2027 | D68: 2026 | E68: 249300 | F68: 900 | G68: Wire Transfer | H68: Boston | I68: =IF(AND(OR(Dashboard!$B$3="Todos",B68=Dashboard!$B$3),OR(Dashboard!$E$3="Todos",H68=Dashboard!$E$3),OR(Dashboard!$H$3="Todos",C68=Dashboard!$H$3),OR(Dashboard!$K$3="Todos",G68=Dashboard!$K$3)),1,0) -> 1
...
